<!-- https://mujoco.readthedocs.io/en/latest/overview.html?highlight=hello.xml#examples -->
<mujoco>
  <compiler angle="radian"/>
  <option gravity = "0 -9.81 0" timestep=".005"/>
  <default>
    <geom solimp=".9 .99 .005" solref=".015 1" friction="1 0.005 0.0001"/>
  </default>
  <worldbody>
    <camera name="top" mode="fixed" pos="0 0 6" euler="0 0 0"/>
    <light diffuse="0 0 0" pos="0 0 10" dir="0 0 -1"/>
    <site name="origin" size="0.1" rgba="1 1 1 .3" pos="0 0 0"/>
    <!--<geom type="sphere" size="0.2" rgba="1 1 1 .3" pos="0 0 0" contype="2"-->
      <!--conaffinity="2"/>-->
    <body pos="0 0 0">
      <joint name="joint0" type="hinge" axis = "0 0 -1" pos = "0 0 0"
        stiffness = "0" damping="2" range = "-2.1 2.1" limited = "true"/>
      <geom name="arm1" type="cylinder" size="0.05" fromto="0 0 0 1 0 0"
        rgba="1 0 0 1" density="50000"/>
      <body pos="1 0 0">
        <joint name="joint1" type="hinge" axis = "0 0 1" pos = "0 0 0"
          damping="2"
          range = "0 .8" limited = "true"
          />
        <geom name="arm2" type="cylinder" size="0.05" fromto="0 0 0 1 0 0"
          rgba="0 1 0 1" density="50000"/>
        <site name="elbow" size="0.1" pos="0 0 0"/>
          <!--springref=".33" stiffness="10"-->
        <body pos="1 0 0">
            <site name="tip" size="0.1" pos="0 0 0"/>
            <geom name="tip_body" type="sphere" size="0.1" pos="0 0 0"
              rgba="1 1 1 1" density="100000"/>
        </body>
      </body>
    </body>
    <!--<body name="lever" pos="2.2 0 0">-->
      <!--<geom type="box" size=".7 .01 .3" rgba="1 1 1 1" pos="0 0 0"-->
        <!--density="100"/>-->
      <!--<joint name="leverjoint" type="hinge" axis = "0 0 1" pos = ".7 0 0"-->
        <!--stiffness="500" damping="5" limited="true" range="0 .3"-->
        <!--solimplimit=".9 .99 .005" solreflimit=".015 1"/>-->
    <!--</body>-->
    <body pos="2.2 0 0">
      <site name="target1" size="0.1" pos=".2 -.643 0"/>
    </body>
    <body pos="2.2 0 0">
      <site name="target2" size="0.1" pos="0 1.1 0"/>
    </body>
  <!--<body pos="0 0 0">-->
      <!--<site name="target" size="0.1" pos="1.47 -.63 0"/>-->
  <!--</body>-->
  </worldbody>

  <actuator>
    <motor name="torque0" joint="joint0"  gear="15" />
    <motor name="torque1" joint="joint1"  gear="15" />
  </actuator>
  <sensor>
    <touch name="tiptouch" site="tip"/>
  </sensor>
</mujoco>
